<?xml version="1.0"?>
<robot xmlns:sensor="http://playerstage.sourceforge.net/gazebo/xmlschema/#sensor"
       xmlns:controller="http://playerstage.sourceforge.net/gazebo/xmlschema/#controller"
       xmlns:interface="http://playerstage.sourceforge.net/gazebo/xmlschema/#interface"
       xmlns:xacro="http://ros.org/wiki/xacro">

  <property name="turret_mass" value="50.0" />

  <property name="turret_cg_z" value="0.15" />
  <property name="turret_tilt_joint_x" value="0.05555" />
  <property name="turret_tilt_joint_y" value="0.0" />
  <property name="turret_tilt_joint_z" value="0.285" />

  <property name="turret_pan_lower_limit" value="-2.356194" />
  <property name="turret_pan_upper_limit" value="2.356194" />
  <property name="turret_tilt_lower_limit" value="-0.785398" />
  <property name="turret_tilt_upper_limit" value="0.785398" />

  <property name="g_paintball_y" value="0.0012" />

  <property name="g_moog_x" value="-0.10872" />  
  <property name="g_moog_y" value="0.0" />
  <property name="g_moog_z" value="0.5414" />

  <xacro:macro name="landshark_turret" params="name parent *origin">

    <joint name="${name}_pan" type="revolute">
      <insert_block name="origin" />
      <parent link="${parent}"/>
      <child link="${name}_link"/>
      <axis xyz="0 0 -1" />
      <limit lower="${turret_pan_lower_limit}" upper="${turret_pan_upper_limit}" effort="7" velocity="15"/>
      <safety_controller  k_velocity="10" />
      <dynamics damping="1.0" friction="0.0" />
    </joint>

    <link name="${name}_link">
      <inertial>
        <mass value="${turret_mass}" />
        <origin xyz="0 0 ${turret_cg_z}" />
        <inertia ixx="1" ixy="0" ixz="0"
                 iyy="1" iyz="0" izz="1" />
      </inertial>

<!--      <visual>-->
<!--        <origin xyz="0 0 0" rpy="0 0 0" />-->
<!--        <geometry>-->
<!--          <mesh filename="package://landshark_description/meshes/landshark_turret.STL" scale="0.001 0.001 0.001"/>-->
<!--        </geometry>-->
<!--        -->
<!--        <material name="Beige" />-->
<!--      </visual>-->

      <collision>
        <origin xyz="0 0 0" rpy="0 0 0" />
        <geometry>
          <mesh filename="package://landshark_description/meshes/landshark_turret_collision.STL" scale="0.001 0.001 0.001"/>
        </geometry>
      </collision>
    </link>

    <joint name="${name}_tilt" type="revolute">
      <origin xyz="${turret_tilt_joint_x} ${turret_tilt_joint_y} ${turret_tilt_joint_z}" />
      <parent link="${name}_link"/>
      <child link="${name}_tilt_link"/>
      <axis xyz="0 -1 0" />
      <limit lower="${turret_tilt_lower_limit}" upper="${turret_tilt_upper_limit}" effort="7" velocity="15"/>
      <safety_controller  k_velocity="10" />
      <dynamics damping="1.0" friction="0.0" />
    </joint>
    
    <link name="${name}_tilt_link">
      <inertial>
        <mass value="0.01" />
        <origin xyz="0 0 0" />
        <inertia ixx="0.01" ixy="0" ixz="0"
                 iyy="0.01" iyz="0" izz="0.01" />
      </inertial>

      <visual>
        <origin xyz="0 0 0" rpy="0 0 0" />
        <geometry>
          <box size="0.01 0.01 0.01"/>
        </geometry>
        
        <material name="White" />
      </visual>

      <collision>
        <origin xyz="0 0 0" rpy="0 0 0" />
        <geometry>
          <box size="0.01 0.01 0.01"/>
        </geometry>
      </collision>
    </link>
    
    <!-- Paintball -->
    <xacro:landshark_paintball name="paintball" parent="${name}_tilt_link">
      <origin xyz="0 ${g_paintball_y} 0" rpy="0 0 0" />
    </xacro:landshark_paintball>

    <!-- Moog -->
    <xacro:landshark_moog name="moog" parent="${name}_link">
      <origin xyz="${g_moog_x} ${g_moog_y} ${g_moog_z}" rpy="0 0 0" />
    </xacro:landshark_moog>

  </xacro:macro>

</robot>
