<?xml version="1.0"?>
<robot xmlns:sensor="http://playerstage.sourceforge.net/gazebo/xmlschema/#sensor"
       xmlns:controller="http://playerstage.sourceforge.net/gazebo/xmlschema/#controller"
       xmlns:interface="http://playerstage.sourceforge.net/gazebo/xmlschema/#interface"
       xmlns:xacro="http://ros.org/wiki/xacro">

  <property name="moog_mass" value="4.0" />

  <property name="moog_cg_z" value="0.0" />
  <property name="moog_tilt_joint_z" value="0.0" />
  <property name="moog_tilt_joint_x" value="0.0" />

  <property name="g_moog_camera_x" value="0.10795" />
  <property name="g_moog_camera_y" value="0.1336" />
  <property name="g_moog_camera_z" value="0.0" />

  <property name="moog_tilt_lower_limit" value="-1.57" />
  <property name="moog_tilt_upper_limit" value="1.57" />

  <xacro:macro name="landshark_moog" params="name parent *origin">

    <joint name="${name}_pan" type="continuous">
      <insert_block name="origin" />
      <parent link="${parent}"/>
      <child link="${name}_link"/>
      <axis xyz="0 0 1" />
      <limit effort="7" velocity="15"/>
      <safety_controller  k_velocity="10" />
      <dynamics damping="1.0" friction="0.0" />
    </joint>

    <link name="${name}_link">
      <inertial>
        <mass value="${moog_mass}" />
        <origin xyz="0 0 ${moog_cg_z}" />
        <inertia ixx="0.1" ixy="0" ixz="0"
                 iyy="0.1" iyz="0" izz="0.1" />
      </inertial>

      <visual>
        <origin xyz="0 0 0" rpy="0 0 0" />
        <geometry>
          <mesh filename="package://landshark_description/meshes/landshark_moog.STL" scale="0.001 0.001 0.001"/>
        </geometry>
        
        <material name="Beige" />
      </visual>

      <collision>
        <origin xyz="0 0 0" rpy="0 0 0" />
        <geometry>
          <mesh filename="package://landshark_description/meshes/landshark_moog_collision.STL" scale="0.001 0.001 0.001"/>
        </geometry>
      </collision>
    </link>

    <joint name="${name}_tilt" type="revolute">
      <origin xyz="${moog_tilt_joint_x} 0 ${moog_tilt_joint_z}" />
      <parent link="${name}_link"/>
      <child link="${name}_tilt_link"/>
      <axis xyz="0 -1 0" />
      <limit lower="${moog_tilt_lower_limit}" upper="${moog_tilt_upper_limit}" effort="7" velocity="15"/>
      <safety_controller  k_velocity="10" />
      <dynamics damping="1.0" friction="0.0" />
    </joint>
    
    <link name="${name}_tilt_link">
      <inertial>
        <mass value="0.01" />
        <origin xyz="0 0 0" />
        <inertia ixx="0.01" ixy="0" ixz="0"
                 iyy="0.01" iyz="0" izz="0.01" />
      </inertial>

      <visual>
        <origin xyz="0 0 0" rpy="0 0 0" />
        <geometry>
          <mesh filename="package://landshark_description/meshes/landshark_moog_camera.STL" scale="0.001 0.001 0.001"/>
        </geometry>
        
        <material name="Beige" />
      </visual>

      <collision>
        <origin xyz="0 0 0" rpy="0 0 0" />
        <geometry>
          <mesh filename="package://landshark_description/meshes/landshark_moog_camera_collision.STL" scale="0.001 0.001 0.001"/>
        </geometry>
      </collision>
    </link>

    <xacro:camera_moog name="moog_right_camera" parent="${name}_tilt_link">
      <origin xyz="${g_moog_camera_x} ${-g_moog_camera_y} ${g_moog_camera_z}" rpy="0 0 0" />
    </xacro:camera_moog>

    <xacro:camera_moog name="moog_left_camera" parent="${name}_tilt_link">
      <origin xyz="${g_moog_camera_x} ${g_moog_camera_y} ${g_moog_camera_z}" rpy="0 0 0" />
    </xacro:camera_moog>

  </xacro:macro>

</robot>
